Workbook
Name Cate: 'H.W&S.W&Services'!$T$1:$T$3
Name Category: 'H.W&S.W&Services'!$T$1:$T$3

Sheet ODOO
A1: SKU | B1: Product Name | C1: Part Number | D1: Description | E1: Qty | F1: Cost | G1: Price | H1: Category | I1: start date | J1: End date
A2: =IF(C2="","",RANDBETWEEN(1,10000000000)&B2&LEFT(D2,10)) -> 22573866712323232Nutanix Ha | B2: =IF('H.W&S.W&Services'!C16=0,"",'H.W&S.W&Services'!C16) -> 2323232 | C2: =IF('H.W&S.W&Services'!C16=0,"",'H.W&S.W&Services'!C16) -> 2323232 | D2: =IF('H.W&S.W&Services'!H16=0,"",'H.W&S.W&Services'!H16) -> Nutanix Hardware Platform * NX-8150-G9, 1 Node Configuration Nutanix Software * Foundation - Hypervisor Agnostic Installer * Controller VM * Prism Management * Starter License Entitlement | E2: =IF('H.W&S.W&Services'!I16=0,"",'H.W&S.W&Services'!I16) -> 3 | F2: =IF('H.W&S.W&Services'!J16=0,"",'H.W&S.W&Services'!J16) | G2: =IF('H.W&S.W&Services'!O16=0,"",'H.W&S.W&Services'!O16) | H2: =IF('H.W&S.W&Services'!B16=0,"",'H.W&S.W&Services'!B16) & IF('H.W&S.W&Services'!F16=0,""," / "&'H.W&S.W&Services'!F16) & IF('H.W&S.W&Services'!G16=0,""," / "&'H.W&S.W&Services'!G16) -> Hardware / Nutanix / New | I2: =IF('H.W&S.W&Services'!D16=0,"",'H.W&S.W&Services'!D16) -> 12-03-2025 | J2: =IF('H.W&S.W&Services'!E16=0,"",'H.W&S.W&Services'!E16) -> 12-06-2025
A3: =IF(C3="","",RANDBETWEEN(1,10000000000)&B3&LEFT(D3,10)) -> 2384440886334343Intel Xeon | B3: =IF('H.W&S.W&Services'!C17=0,"",'H.W&S.W&Services'!C17) -> 334343 | C3: =IF('H.W&S.W&Services'!C17=0,"",'H.W&S.W&Services'!C17) -> 334343 | D3: =IF('H.W&S.W&Services'!H17=0,"",'H.W&S.W&Services'!H17) -> Intel Xeon-Gold 6548Y+ processor (2.5 GHz/ 32-core/ 250W,Emerald Rapids) | E3: =IF('H.W&S.W&Services'!I17=0,"",'H.W&S.W&Services'!I17) -> 6 | F3: =IF('H.W&S.W&Services'!J17=0,"",'H.W&S.W&Services'!J17) | G3: =IF('H.W&S.W&Services'!O17=0,"",'H.W&S.W&Services'!O17) | H3: =IF('H.W&S.W&Services'!B17=0,"",'H.W&S.W&Services'!B17) & IF('H.W&S.W&Services'!F17=0,""," / "&'H.W&S.W&Services'!F17) & IF('H.W&S.W&Services'!G17=0,""," / "&'H.W&S.W&Services'!G17) -> Software / Nutanix / New | I3: =IF('H.W&S.W&Services'!D17=0,"",'H.W&S.W&Services'!D17) -> 12-03-2025 | J3: =IF('H.W&S.W&Services'!E17=0,"",'H.W&S.W&Services'!E17) -> 12-06-2025
A4: =IF(C4="","",RANDBETWEEN(1,10000000000)&B4&LEFT(D4,10)) | B4: =IF('H.W&S.W&Services'!C18=0,"",'H.W&S.W&Services'!C18) | C4: =IF('H.W&S.W&Services'!C18=0,"",'H.W&S.W&Services'!C18) | D4: =IF('H.W&S.W&Services'!H18=0,"",'H.W&S.W&Services'!H18) | E4: =IF('H.W&S.W&Services'!I18=0,"",'H.W&S.W&Services'!I18) | F4: =IF('H.W&S.W&Services'!J18=0,"",'H.W&S.W&Services'!J18) | G4: =IF('H.W&S.W&Services'!O18=0,"",'H.W&S.W&Services'!O18) | H4: =IF('H.W&S.W&Services'!B18=0,"",'H.W&S.W&Services'!B18) & IF('H.W&S.W&Services'!F18=0,""," / "&'H.W&S.W&Services'!F18) & IF('H.W&S.W&Services'!G18=0,""," / "&'H.W&S.W&Services'!G18) | I4: =IF('H.W&S.W&Services'!D18=0,"",'H.W&S.W&Services'!D18) | J4: =IF('H.W&S.W&Services'!E18=0,"",'H.W&S.W&Services'!E18)
A5: =IF(C5="","",RANDBETWEEN(1,10000000000)&B5&LEFT(D5,10)) | B5: =IF('H.W&S.W&Services'!C19=0,"",'H.W&S.W&Services'!C19) | C5: =IF('H.W&S.W&Services'!C19=0,"",'H.W&S.W&Services'!C19) | D5: =IF('H.W&S.W&Services'!H19=0,"",'H.W&S.W&Services'!H19) | E5: =IF('H.W&S.W&Services'!I19=0,"",'H.W&S.W&Services'!I19) | F5: =IF('H.W&S.W&Services'!J19=0,"",'H.W&S.W&Services'!J19) | G5: =IF('H.W&S.W&Services'!O19=0,"",'H.W&S.W&Services'!O19) | H5: =IF('H.W&S.W&Services'!B19=0,"",'H.W&S.W&Services'!B19) & IF('H.W&S.W&Services'!F19=0,""," / "&'H.W&S.W&Services'!F19) & IF('H.W&S.W&Services'!G19=0,""," / "&'H.W&S.W&Services'!G19) | I5: =IF('H.W&S.W&Services'!D19=0,"",'H.W&S.W&Services'!D19) | J5: =IF('H.W&S.W&Services'!E19=0,"",'H.W&S.W&Services'!E19)
A6: =IF(C6="","",RANDBETWEEN(1,10000000000)&B6&LEFT(D6,10)) | B6: =IF('H.W&S.W&Services'!C20=0,"",'H.W&S.W&Services'!C20) | C6: =IF('H.W&S.W&Services'!C20=0,"",'H.W&S.W&Services'!C20) | D6: =IF('H.W&S.W&Services'!H20=0,"",'H.W&S.W&Services'!H20) | E6: =IF('H.W&S.W&Services'!I20=0,"",'H.W&S.W&Services'!I20) | F6: =IF('H.W&S.W&Services'!J20=0,"",'H.W&S.W&Services'!J20) | G6: =IF('H.W&S.W&Services'!O20=0,"",'H.W&S.W&Services'!O20) | H6: =IF('H.W&S.W&Services'!B20=0,"",'H.W&S.W&Services'!B20) & IF('H.W&S.W&Services'!F20=0,""," / "&'H.W&S.W&Services'!F20) & IF('H.W&S.W&Services'!G20=0,""," / "&'H.W&S.W&Services'!G20) | I6: =IF('H.W&S.W&Services'!D20=0,"",'H.W&S.W&Services'!D20) | J6: =IF('H.W&S.W&Services'!E20=0,"",'H.W&S.W&Services'!E20)
A7: =IF(C7="","",RANDBETWEEN(1,10000000000)&B7&LEFT(D7,10)) | B7: =IF('H.W&S.W&Services'!C21=0,"",'H.W&S.W&Services'!C21) | C7: =IF('H.W&S.W&Services'!C21=0,"",'H.W&S.W&Services'!C21) | D7: =IF('H.W&S.W&Services'!H21=0,"",'H.W&S.W&Services'!H21) | E7: =IF('H.W&S.W&Services'!I21=0,"",'H.W&S.W&Services'!I21) | F7: =IF('H.W&S.W&Services'!J21=0,"",'H.W&S.W&Services'!J21) | G7: =IF('H.W&S.W&Services'!O21=0,"",'H.W&S.W&Services'!O21) | H7: =IF('H.W&S.W&Services'!B21=0,"",'H.W&S.W&Services'!B21) & IF('H.W&S.W&Services'!F21=0,""," / "&'H.W&S.W&Services'!F21) & IF('H.W&S.W&Services'!G21=0,""," / "&'H.W&S.W&Services'!G21) | I7: =IF('H.W&S.W&Services'!D21=0,"",'H.W&S.W&Services'!D21) | J7: =IF('H.W&S.W&Services'!E21=0,"",'H.W&S.W&Services'!E21)
A8: =IF(C8="","",RANDBETWEEN(1,10000000000)&B8&LEFT(D8,10)) | B8: =IF('H.W&S.W&Services'!C22=0,"",'H.W&S.W&Services'!C22) | C8: =IF('H.W&S.W&Services'!C22=0,"",'H.W&S.W&Services'!C22) | D8: =IF('H.W&S.W&Services'!H22=0,"",'H.W&S.W&Services'!H22) | E8: =IF('H.W&S.W&Services'!I22=0,"",'H.W&S.W&Services'!I22) | F8: =IF('H.W&S.W&Services'!J22=0,"",'H.W&S.W&Services'!J22) | G8: =IF('H.W&S.W&Services'!O22=0,"",'H.W&S.W&Services'!O22) | H8: =IF('H.W&S.W&Services'!B22=0,"",'H.W&S.W&Services'!B22) & IF('H.W&S.W&Services'!F22=0,""," / "&'H.W&S.W&Services'!F22) & IF('H.W&S.W&Services'!G22=0,""," / "&'H.W&S.W&Services'!G22) | I8: =IF('H.W&S.W&Services'!D22=0,"",'H.W&S.W&Services'!D22) | J8: =IF('H.W&S.W&Services'!E22=0,"",'H.W&S.W&Services'!E22)
A9: =IF(C9="","",RANDBETWEEN(1,10000000000)&B9&LEFT(D9,10)) | B9: =IF('H.W&S.W&Services'!C23=0,"",'H.W&S.W&Services'!C23) | C9: =IF('H.W&S.W&Services'!C23=0,"",'H.W&S.W&Services'!C23) | D9: =IF('H.W&S.W&Services'!H23=0,"",'H.W&S.W&Services'!H23) | E9: =IF('H.W&S.W&Services'!I23=0,"",'H.W&S.W&Services'!I23) | F9: =IF('H.W&S.W&Services'!J23=0,"",'H.W&S.W&Services'!J23) | G9: =IF('H.W&S.W&Services'!O23=0,"",'H.W&S.W&Services'!O23) | H9: =IF('H.W&S.W&Services'!B23=0,"",'H.W&S.W&Services'!B23) & IF('H.W&S.W&Services'!F23=0,""," / "&'H.W&S.W&Services'!F23) & IF('H.W&S.W&Services'!G23=0,""," / "&'H.W&S.W&Services'!G23) | I9: =IF('H.W&S.W&Services'!D23=0,"",'H.W&S.W&Services'!D23) | J9: =IF('H.W&S.W&Services'!E23=0,"",'H.W&S.W&Services'!E23)
A10: =IF(C10="","",RANDBETWEEN(1,10000000000)&B10&LEFT(D10,10)) | B10: =IF('H.W&S.W&Services'!C24=0,"",'H.W&S.W&Services'!C24) | C10: =IF('H.W&S.W&Services'!C24=0,"",'H.W&S.W&Services'!C24) | D10: =IF('H.W&S.W&Services'!H24=0,"",'H.W&S.W&Services'!H24) | E10: =IF('H.W&S.W&Services'!I24=0,"",'H.W&S.W&Services'!I24) | F10: =IF('H.W&S.W&Services'!J24=0,"",'H.W&S.W&Services'!J24) | G10: =IF('H.W&S.W&Services'!O24=0,"",'H.W&S.W&Services'!O24) | H10: =IF('H.W&S.W&Services'!B24=0,"",'H.W&S.W&Services'!B24) & IF('H.W&S.W&Services'!F24=0,""," / "&'H.W&S.W&Services'!F24) & IF('H.W&S.W&Services'!G24=0,""," / "&'H.W&S.W&Services'!G24) | I10: =IF('H.W&S.W&Services'!D24=0,"",'H.W&S.W&Services'!D24) | J10: =IF('H.W&S.W&Services'!E24=0,"",'H.W&S.W&Services'!E24)
A11: =IF(C11="","",RANDBETWEEN(1,10000000000)&B11&LEFT(D11,10)) | B11: =IF('H.W&S.W&Services'!C25=0,"",'H.W&S.W&Services'!C25) | C11: =IF('H.W&S.W&Services'!C25=0,"",'H.W&S.W&Services'!C25) | D11: =IF('H.W&S.W&Services'!H25=0,"",'H.W&S.W&Services'!H25) | E11: =IF('H.W&S.W&Services'!I25=0,"",'H.W&S.W&Services'!I25) | F11: =IF('H.W&S.W&Services'!J25=0,"",'H.W&S.W&Services'!J25) | G11: =IF('H.W&S.W&Services'!O25=0,"",'H.W&S.W&Services'!O25) | H11: =IF('H.W&S.W&Services'!B25=0,"",'H.W&S.W&Services'!B25) & IF('H.W&S.W&Services'!F25=0,""," / "&'H.W&S.W&Services'!F25) & IF('H.W&S.W&Services'!G25=0,""," / "&'H.W&S.W&Services'!G25) | I11: =IF('H.W&S.W&Services'!D25=0,"",'H.W&S.W&Services'!D25) | J11: =IF('H.W&S.W&Services'!E25=0,"",'H.W&S.W&Services'!E25)
A12: =IF(C12="","",RANDBETWEEN(1,10000000000)&B12&LEFT(D12,10)) | B12: =IF('H.W&S.W&Services'!C26=0,"",'H.W&S.W&Services'!C26) | C12: =IF('H.W&S.W&Services'!C26=0,"",'H.W&S.W&Services'!C26) | D12: =IF('H.W&S.W&Services'!H26=0,"",'H.W&S.W&Services'!H26) | E12: =IF('H.W&S.W&Services'!I26=0,"",'H.W&S.W&Services'!I26) | F12: =IF('H.W&S.W&Services'!J26=0,"",'H.W&S.W&Services'!J26) | G12: =IF('H.W&S.W&Services'!O26=0,"",'H.W&S.W&Services'!O26) | H12: =IF('H.W&S.W&Services'!B26=0,"",'H.W&S.W&Services'!B26) & IF('H.W&S.W&Services'!F26=0,""," / "&'H.W&S.W&Services'!F26) & IF('H.W&S.W&Services'!G26=0,""," / "&'H.W&S.W&Services'!G26) | I12: =IF('H.W&S.W&Services'!D26=0,"",'H.W&S.W&Services'!D26) | J12: =IF('H.W&S.W&Services'!E26=0,"",'H.W&S.W&Services'!E26)
A13: =IF(C13="","",RANDBETWEEN(1,10000000000)&B13&LEFT(D13,10)) | B13: =IF('H.W&S.W&Services'!C27=0,"",'H.W&S.W&Services'!C27) | C13: =IF('H.W&S.W&Services'!C27=0,"",'H.W&S.W&Services'!C27) | D13: =IF('H.W&S.W&Services'!H27=0,"",'H.W&S.W&Services'!H27) | E13: =IF('H.W&S.W&Services'!I27=0,"",'H.W&S.W&Services'!I27) | F13: =IF('H.W&S.W&Services'!J27=0,"",'H.W&S.W&Services'!J27) | G13: =IF('H.W&S.W&Services'!O27=0,"",'H.W&S.W&Services'!O27) | H13: =IF('H.W&S.W&Services'!B27=0,"",'H.W&S.W&Services'!B27) & IF('H.W&S.W&Services'!F27=0,""," / "&'H.W&S.W&Services'!F27) & IF('H.W&S.W&Services'!G27=0,""," / "&'H.W&S.W&Services'!G27) | I13: =IF('H.W&S.W&Services'!D27=0,"",'H.W&S.W&Services'!D27) | J13: =IF('H.W&S.W&Services'!E27=0,"",'H.W&S.W&Services'!E27)
... A400: =IF(C400="","",RANDBETWEEN(1,10000000000)&B400&LEFT(D400,10)) | B400: =IF('H.W&S.W&Services'!C414=0,"",'H.W&S.W&Services'!C414) | C400: =IF('H.W&S.W&Services'!C414=0,"",'H.W&S.W&Services'!C414) | D400: =IF('H.W&S.W&Services'!H414=0,"",'H.W&S.W&Services'!H414) | E400: =IF('H.W&S.W&Services'!I414=0,"",'H.W&S.W&Services'!I414) | F400: =IF('H.W&S.W&Services'!J414=0,"",'H.W&S.W&Services'!J414) | G400: =IF('H.W&S.W&Services'!O414=0,"",'H.W&S.W&Services'!O414) | H400: =IF('H.W&S.W&Services'!B414=0,"",'H.W&S.W&Services'!B414) & IF('H.W&S.W&Services'!F414=0,""," / "&'H.W&S.W&Services'!F414) & IF('H.W&S.W&Services'!G414=0,""," / "&'H.W&S.W&Services'!G414) | I400: =IF('H.W&S.W&Services'!D414=0,"",'H.W&S.W&Services'!D414) | J400: =IF('H.W&S.W&Services'!E414=0,"",'H.W&S.W&Services'!E414)

Sheet H.W&S.W&Services
B1: Business Case Analysis
Z2: Lenovo
A3: Date | Z3: HP
A4: 45728 | Z4: IBM
A5: Customer Name | H5: Customer Payment terms | L5: VAT | M5: No | O5: VAT | P5: yes | Z5: Veeam
A6: Petrobel | H6: 50% Down Payment, 30% after receiving license, 20% after Final Installation Report | L6: Total Net Cost | M6: =SUBTOTAL(9,Table2[[#All],[Total Cost]]) -> 0 | O6: Total Net Sales | P6: =SUBTOTAL(9,'H.W&S.W&Services'!$P$15:$P$200) -> 0 | Z6: Storage
A7: Distributor Name | H7: Supplier Payment Terms | L7: Vat Value | M7: =IF(M5="Yes",M6*14%,0) -> 0 | O7: Vat Value | P7: =IF(P5="Yes",P6*14%,0) -> 0 | Z7: FortiGate
A8: Metra | H8: As Agreed With METRA | L8: Gross Cost | M8: =M6+M7 -> 0 | O8: Gross Sale | P8: =P6+P7 -> 0 | Z8: Postgres
A9: Cost Currency | O9: Total Margin | P9: =(P6-M6)/M6 -> #DIV/0! | Z9: PaloAlto
A10: USD | Z10: Fortinet
A11: Sales Currency | Z11: Cisco
A12: USD | Z12: Juniper
Z13: Training
Z14: Vmware
A15: NO. | B15: Product | C15: Part Number | D15: Satrt Date | E15: End Date | F15: Vendor | G15: Category | H15: Description | I15: Quantity | J15: Unit cost | K15: FX | L15: Unit cost FX | M15: Total Cost | N15: % | O15: Unit Sales | P15: Total Sales | Z15: Lansweeper
A16: 1 | B16: Hardware | C16: 2323232 | D16: 12-03-2025 | E16: 12-06-2025 | F16: Nutanix | G16: New | H16: Nutanix Hardware Platform * NX-8150-G9, 1 Node Configuration Nutanix Software * Foundation - Hypervisor Agnostic Installer * Controller VM * Prism Management * Starter License Entitlement | I16: 3 | L16: =(Table210[[#This Row],[Unit cost]]*Table311[[#This Row],[FX]])+Table210[[#This Row],[Unit cost]] -> 0 | M16: ='H.W&S.W&Services'!$I16*Table2[[#This Row],[Unit cost FX]] -> 0 | O16: =(Table2[[#This Row],[Unit cost FX]]*Table3[[#This Row],[%]])+Table2[[#This Row],[Unit cost FX]] -> 0 | P16: ='H.W&S.W&Services'!$O16*'H.W&S.W&Services'!$I16 -> 0 | Z16: Ncomputing
B17: Software | C17: 334343 | D17: 12-03-2025 | E17: 12-06-2025 | F17: Nutanix | G17: New | H17: Intel Xeon-Gold 6548Y+ processor (2.5 GHz/ 32-core/ 250W,Emerald Rapids) | I17: 6 | L17: =(Table210[[#This Row],[Unit cost]]*Table311[[#This Row],[FX]])+Table210[[#This Row],[Unit cost]] -> 0 | M17: ='H.W&S.W&Services'!$I17*Table2[[#This Row],[Unit cost FX]] -> 0 | O17: =(Table2[[#This Row],[Unit cost FX]]*Table3[[#This Row],[%]])+Table2[[#This Row],[Unit cost FX]] -> 0 | P17: ='H.W&S.W&Services'!$O17*'H.W&S.W&Services'!$I17 -> 0 | Z17: Dell
L18: =(Table210[[#This Row],[Unit cost]]*Table311[[#This Row],[FX]])+Table210[[#This Row],[Unit cost]] -> 0 | M18: ='H.W&S.W&Services'!$I18*Table2[[#This Row],[Unit cost FX]] -> 0 | O18: =(Table2[[#This Row],[Unit cost FX]]*Table3[[#This Row],[%]])+Table2[[#This Row],[Unit cost FX]] -> 0 | P18: ='H.W&S.W&Services'!$O18*'H.W&S.W&Services'!$I18 -> 0 | Z18: Ivanti
L19: =(Table210[[#This Row],[Unit cost]]*Table311[[#This Row],[FX]])+Table210[[#This Row],[Unit cost]] -> 0 | M19: ='H.W&S.W&Services'!$I19*Table2[[#This Row],[Unit cost FX]] -> 0 | O19: =(Table2[[#This Row],[Unit cost FX]]*Table3[[#This Row],[%]])+Table2[[#This Row],[Unit cost FX]] -> 0 | P19: ='H.W&S.W&Services'!$O19*'H.W&S.W&Services'!$I19 -> 0 | Z19: Tenable
L20: =(Table210[[#This Row],[Unit cost]]*Table311[[#This Row],[FX]])+Table210[[#This Row],[Unit cost]] -> 0 | M20: ='H.W&S.W&Services'!$I20*Table2[[#This Row],[Unit cost FX]] -> 0 | O20: =(Table2[[#This Row],[Unit cost FX]]*Table3[[#This Row],[%]])+Table2[[#This Row],[Unit cost FX]] -> 0 | P20: ='H.W&S.W&Services'!$O20*'H.W&S.W&Services'!$I20 -> 0 | Z20: CrowdStrike
L21: =(Table210[[#This Row],[Unit cost]]*Table311[[#This Row],[FX]])+Table210[[#This Row],[Unit cost]] -> 0 | M21: ='H.W&S.W&Services'!$I21*Table2[[#This Row],[Unit cost FX]] -> 0 | O21: =(Table2[[#This Row],[Unit cost FX]]*Table3[[#This Row],[%]])+Table2[[#This Row],[Unit cost FX]] -> 0 | P21: ='H.W&S.W&Services'!$O21*'H.W&S.W&Services'!$I21 -> 0 | Z21: USB
L22: =(Table210[[#This Row],[Unit cost]]*Table311[[#This Row],[FX]])+Table210[[#This Row],[Unit cost]] -> 0 | M22: ='H.W&S.W&Services'!$I22*Table2[[#This Row],[Unit cost FX]] -> 0 | O22: =(Table2[[#This Row],[Unit cost FX]]*Table3[[#This Row],[%]])+Table2[[#This Row],[Unit cost FX]] -> 0 | P22: ='H.W&S.W&Services'!$O22*'H.W&S.W&Services'!$I22 -> 0 | Z22: Fujitsu
L23: =(Table210[[#This Row],[Unit cost]]*Table311[[#This Row],[FX]])+Table210[[#This Row],[Unit cost]] -> 0 | M23: ='H.W&S.W&Services'!$I23*Table2[[#This Row],[Unit cost FX]] -> 0 | O23: =(Table2[[#This Row],[Unit cost FX]]*Table3[[#This Row],[%]])+Table2[[#This Row],[Unit cost FX]] -> 0 | P23: ='H.W&S.W&Services'!$O23*'H.W&S.W&Services'!$I23 -> 0 | Z23: Barracuda
L24: =(Table210[[#This Row],[Unit cost]]*Table311[[#This Row],[FX]])+Table210[[#This Row],[Unit cost]] -> 0 | M24: ='H.W&S.W&Services'!$I24*Table2[[#This Row],[Unit cost FX]] -> 0 | O24: =(Table2[[#This Row],[Unit cost FX]]*Table3[[#This Row],[%]])+Table2[[#This Row],[Unit cost FX]] -> 0 | P24: ='H.W&S.W&Services'!$O24*'H.W&S.W&Services'!$I24 -> 0 | Z24: Netwitness
L25: =(Table210[[#This Row],[Unit cost]]*Table311[[#This Row],[FX]])+Table210[[#This Row],[Unit cost]] -> 0 | M25: ='H.W&S.W&Services'!$I25*Table2[[#This Row],[Unit cost FX]] -> 0 | O25: =(Table2[[#This Row],[Unit cost FX]]*Table3[[#This Row],[%]])+Table2[[#This Row],[Unit cost FX]] -> 0 | P25: ='H.W&S.W&Services'!$O25*'H.W&S.W&Services'!$I25 -> 0 | Z25: Fortra
L26: =(Table210[[#This Row],[Unit cost]]*Table311[[#This Row],[FX]])+Table210[[#This Row],[Unit cost]] -> 0 | M26: ='H.W&S.W&Services'!$I26*Table2[[#This Row],[Unit cost FX]] -> 0 | O26: =(Table2[[#This Row],[Unit cost FX]]*Table3[[#This Row],[%]])+Table2[[#This Row],[Unit cost FX]] -> 0 | P26: ='H.W&S.W&Services'!$O26*'H.W&S.W&Services'!$I26 -> 0 | Z26: Netwrix
L27: =(Table210[[#This Row],[Unit cost]]*Table311[[#This Row],[FX]])+Table210[[#This Row],[Unit cost]] -> 0 | M27: ='H.W&S.W&Services'!$I27*Table2[[#This Row],[Unit cost FX]] -> 0 | O27: =(Table2[[#This Row],[Unit cost FX]]*Table3[[#This Row],[%]])+Table2[[#This Row],[Unit cost FX]] -> 0 | P27: ='H.W&S.W&Services'!$O27*'H.W&S.W&Services'!$I27 -> 0 | Z27: Kaspersky
L28: =(Table210[[#This Row],[Unit cost]]*Table311[[#This Row],[FX]])+Table210[[#This Row],[Unit cost]] -> 0 | M28: ='H.W&S.W&Services'!$I28*Table2[[#This Row],[Unit cost FX]] -> 0 | O28: =(Table2[[#This Row],[Unit cost FX]]*Table3[[#This Row],[%]])+Table2[[#This Row],[Unit cost FX]] -> 0 | P28: ='H.W&S.W&Services'!$O28*'H.W&S.W&Services'!$I28 -> 0 | Z28: Huawei
L29: =(Table210[[#This Row],[Unit cost]]*Table311[[#This Row],[FX]])+Table210[[#This Row],[Unit cost]] -> 0 | M29: ='H.W&S.W&Services'!$I29*Table2[[#This Row],[Unit cost FX]] -> 0 | O29: =(Table2[[#This Row],[Unit cost FX]]*Table3[[#This Row],[%]])+Table2[[#This Row],[Unit cost FX]] -> 0 | P29: ='H.W&S.W&Services'!$O29*'H.W&S.W&Services'!$I29 -> 0 | Z29: Xfusion
... L33: =(Table210[[#This Row],[Unit cost]]*Table311[[#This Row],[FX]])+Table210[[#This Row],[Unit cost]] -> 0 | M33: ='H.W&S.W&Services'!$I33*Table2[[#This Row],[Unit cost FX]] -> 0 | O33: =(Table2[[#This Row],[Unit cost FX]]*Table3[[#This Row],[%]])+Table2[[#This Row],[Unit cost FX]] -> 0 | P33: ='H.W&S.W&Services'!$O33*'H.W&S.W&Services'!$I33 -> 0 | Z33: Elastic
L34: =(Table210[[#This Row],[Unit cost]]*Table311[[#This Row],[FX]])+Table210[[#This Row],[Unit cost]] -> 0 | M34: ='H.W&S.W&Services'!$I34*Table2[[#This Row],[Unit cost FX]] -> 0 | O34: =(Table2[[#This Row],[Unit cost FX]]*Table3[[#This Row],[%]])+Table2[[#This Row],[Unit cost FX]] -> 0 | P34: ='H.W&S.W&Services'!$O34*'H.W&S.W&Services'!$I34 -> 0
L35: =(Table210[[#This Row],[Unit cost]]*Table311[[#This Row],[FX]])+Table210[[#This Row],[Unit cost]] -> 0 | M35: ='H.W&S.W&Services'!$I35*Table2[[#This Row],[Unit cost FX]] -> 0 | O35: =(Table2[[#This Row],[Unit cost FX]]*Table3[[#This Row],[%]])+Table2[[#This Row],[Unit cost FX]] -> 0 | P35: ='H.W&S.W&Services'!$O35*'H.W&S.W&Services'!$I35 -> 0
L36: =(Table210[[#This Row],[Unit cost]]*Table311[[#This Row],[FX]])+Table210[[#This Row],[Unit cost]] -> 0 | M36: ='H.W&S.W&Services'!$I36*Table2[[#This Row],[Unit cost FX]] -> 0 | O36: =(Table2[[#This Row],[Unit cost FX]]*Table3[[#This Row],[%]])+Table2[[#This Row],[Unit cost FX]] -> 0 | P36: ='H.W&S.W&Services'!$O36*'H.W&S.W&Services'!$I36 -> 0
L37: =(Table210[[#This Row],[Unit cost]]*Table311[[#This Row],[FX]])+Table210[[#This Row],[Unit cost]] -> 0 | M37: ='H.W&S.W&Services'!$I37*Table2[[#This Row],[Unit cost FX]] -> 0 | O37: =(Table2[[#This Row],[Unit cost FX]]*Table3[[#This Row],[%]])+Table2[[#This Row],[Unit cost FX]] -> 0 | P37: ='H.W&S.W&Services'!$O37*'H.W&S.W&Services'!$I37 -> 0
L38: =(Table210[[#This Row],[Unit cost]]*Table311[[#This Row],[FX]])+Table210[[#This Row],[Unit cost]] -> 0 | M38: ='H.W&S.W&Services'!$I38*Table2[[#This Row],[Unit cost FX]] -> 0 | O38: =(Table2[[#This Row],[Unit cost FX]]*Table3[[#This Row],[%]])+Table2[[#This Row],[Unit cost FX]] -> 0 | P38: ='H.W&S.W&Services'!$O38*'H.W&S.W&Services'!$I38 -> 0
L39: =(Table210[[#This Row],[Unit cost]]*Table311[[#This Row],[FX]])+Table210[[#This Row],[Unit cost]] -> 0 | M39: ='H.W&S.W&Services'!$I39*Table2[[#This Row],[Unit cost FX]] -> 0 | O39: =(Table2[[#This Row],[Unit cost FX]]*Table3[[#This Row],[%]])+Table2[[#This Row],[Unit cost FX]] -> 0 | P39: ='H.W&S.W&Services'!$O39*'H.W&S.W&Services'!$I39 -> 0
L40: =(Table210[[#This Row],[Unit cost]]*Table311[[#This Row],[FX]])+Table210[[#This Row],[Unit cost]] -> 0 | M40: ='H.W&S.W&Services'!$I40*Table2[[#This Row],[Unit cost FX]] -> 0 | O40: =(Table2[[#This Row],[Unit cost FX]]*Table3[[#This Row],[%]])+Table2[[#This Row],[Unit cost FX]] -> 0 | P40: ='H.W&S.W&Services'!$O40*'H.W&S.W&Services'!$I40 -> 0
L41: =(Table210[[#This Row],[Unit cost]]*Table311[[#This Row],[FX]])+Table210[[#This Row],[Unit cost]] -> 0 | M41: ='H.W&S.W&Services'!$I41*Table2[[#This Row],[Unit cost FX]] -> 0 | O41: =(Table2[[#This Row],[Unit cost FX]]*Table3[[#This Row],[%]])+Table2[[#This Row],[Unit cost FX]] -> 0 | P41: ='H.W&S.W&Services'!$O41*'H.W&S.W&Services'!$I41 -> 0
L42: =(Table210[[#This Row],[Unit cost]]*Table311[[#This Row],[FX]])+Table210[[#This Row],[Unit cost]] -> 0 | M42: ='H.W&S.W&Services'!$I42*Table2[[#This Row],[Unit cost FX]] -> 0 | O42: =(Table2[[#This Row],[Unit cost FX]]*Table3[[#This Row],[%]])+Table2[[#This Row],[Unit cost FX]] -> 0 | P42: ='H.W&S.W&Services'!$O42*'H.W&S.W&Services'!$I42 -> 0
L43: =(Table210[[#This Row],[Unit cost]]*Table311[[#This Row],[FX]])+Table210[[#This Row],[Unit cost]] -> 0 | M43: ='H.W&S.W&Services'!$I43*Table2[[#This Row],[Unit cost FX]] -> 0 | O43: =(Table2[[#This Row],[Unit cost FX]]*Table3[[#This Row],[%]])+Table2[[#This Row],[Unit cost FX]] -> 0 | P43: ='H.W&S.W&Services'!$O43*'H.W&S.W&Services'!$I43 -> 0
...

Sheet Sheet1
